<?xml version="1.0" encoding="utf-8"?>
<!-- This URDF was automatically created by SolidWorks to URDF Exporter! Originally created by Stephen Brawner (brawner@gmail.com) 
     Commit Version: 1.6.0-4-g7f85cfe  Build Version: 1.6.7995.38578
     For more information, please see http://wiki.ros.org/sw_urdf_exporter -->
<robot name="New_new_kuavo_3_3">
  <mujoco>
    <compiler strippath="false" discardvisual="false"/>
  </mujoco>
  <link name="world"/>
  <joint name="dummy_joint" type="floating">
    <parent link="world" />
    <child link="base_link" />
  </joint>
  <link name="base_link">
    <inertial>
      <origin
        xyz="-0.00699293960383802 0.00155633220268026 0.152865943474551"
        rpy="0 0 0" />
      <mass
        value="7.71324827879796" />
      <inertia
        ixx="0.0426865291658434"
        ixy="1.85724164379468E-06"
        ixz="0.0010941107421191"
        iyy="0.020412125396821"
        iyz="-3.14875771284261E-06"
        izz="0.0372747742844986" />
    </inertial>
    <visual>
      <origin
        xyz="0 0 0"
        rpy="0 0 0" />
      <geometry>
        <mesh
          filename="../meshes/base_link_simplify.STL" />
      </geometry>
      <material
        name="">
        <color
          rgba="0.862745098039216 0.933333333333333 0.929411764705882 1" />
      </material>
    </visual>
  </link>
  <link name="l_leg_roll">
    <inertial>
      <origin
        xyz="0.0607642758367597 0.00014034128720411 0.00228371917512799"
        rpy="0 0 0" />
      <mass
        value="0.118529537524385" />
      <inertia
        ixx="0.000100527370735922"
        ixy="-1.21001269445094E-09"
        ixz="-5.73994022636998E-06"
        iyy="0.000266846737510275"
        iyz="-1.09965529112337E-07"
        izz="0.000326428442604199" />
    </inertial>
    <visual>
      <origin
        xyz="0 0 0"
        rpy="0 0 0" />
      <geometry>
        <mesh
          filename="../meshes/l_leg_roll_simplify.STL" />
      </geometry>
      <material
        name="">
        <color
          rgba="0.862745098039216 0.933333333333333 0.929411764705882 1" />
      </material>
    </visual>
  </link>
  <joint name="l_leg_roll"
    type="revolute">
    <origin
      xyz="-0.0756149468145449 0.087 -0.0720754569616772"
      rpy="0 0 0" />
    <parent
      link="base_link" />
    <child
      link="l_leg_roll" />
    <axis xyz="1 0 0" />
    <limit
      effort="1000.0" lower="-3.14" upper="3.14" velocity="0.5"/>
  </joint>
  <link name="l_leg_yaw">
    <inertial>
      <origin
        xyz="0.000290902697264877 0.0405087424467619 -0.100846923361789"
        rpy="0 0 0" />
      <mass
        value="0.20405278020544" />
      <inertia
        ixx="0.000304319732135481"
        ixy="6.81277324993593E-07"
        ixz="5.14353295201488E-07"
        iyy="0.000364082147695825"
        iyz="2.16417948537574E-06"
        izz="0.000267287713044087" />
    </inertial>
    <visual>
      <origin
        xyz="0 0 0"
        rpy="0 0 0" />
      <geometry>
        <mesh
          filename="../meshes/l_leg_yaw_simplify.STL" />
      </geometry>
      <material
        name="">
        <color
          rgba="0.862745098039216 0.933333333333333 0.929411764705882 1" />
      </material>
    </visual>
  </link>
  <joint name="l_leg_yaw"
    type="revolute"> <limit effort="1000.0" lower="-3.14" upper="3.14" velocity="0.5"/>
    <origin
      xyz="0.0735 0 0.0130000000000001"
      rpy="0 0 0" />
    <parent
      link="l_leg_roll" />
    <child
      link="l_leg_yaw" />
    <axis xyz="0 0 1" />
  </joint>
  <link name="l_leg_pitch">
    <inertial>
      <origin
        xyz="-0.00528235933691826 -0.0878849862537982 -0.056800998667162"
        rpy="0 0 0" />
      <mass
        value="0.45065011418642" />
      <inertia
        ixx="0.00148456678733155"
        ixy="-2.29184752662021E-05"
        ixz="0.000131476982175566"
        iyy="0.00177807990369305"
        iyz="7.48554604302084E-06"
        izz="0.000394925298656241" />
    </inertial>
    <visual>
      <origin
        xyz="0 0 0"
        rpy="0 0 0" />
      <geometry>
        <mesh
          filename="../meshes/l_leg_pitch_simplify.STL" />
      </geometry>
      <material
        name="">
        <color
          rgba="0.807843137254902 0.843137254901961 0.905882352941176 1" />
      </material>
    </visual>
  </link>
  <joint name="l_leg_pitch"
    type="revolute"> <limit effort="1000.0" lower="-3.14" upper="3.14" velocity="0.5"/>
    <origin
      xyz="0 0.0939999999999999 -0.13645"
      rpy="0 0 0" />
    <parent
      link="l_leg_yaw" />
    <child
      link="l_leg_pitch" />
    <axis xyz="0 1 0" />
  </joint>
  <link name="l_knee">
    <inertial>
      <origin
        xyz="0.000868873637859806 -5.03011046766588E-05 -0.13314742049396"
        rpy="0 0 0" />
      <mass
        value="0.817175320465059" />
      <inertia
        ixx="0.00786383933470876"
        ixy="-3.13623718617422E-08"
        ixz="-7.89544117443064E-05"
        iyy="0.0081080818905141"
        iyz="-6.80654926871359E-05"
        izz="0.000441233410542845" />
    </inertial>
    <visual>
      <origin
        xyz="0 0 0"
        rpy="0 0 0" />
      <geometry>
        <mesh
          filename="../meshes/l_knee_simplify.STL" />
      </geometry>
      <material
        name="">
        <color
          rgba="0.898039215686275 0.917647058823529 0.929411764705882 1" />
      </material>
    </visual>
  </link>
  <joint name="l_knee"
    type="revolute"> <limit effort="1000.0" lower="-3.14" upper="3.14" velocity="0.5"/>
    <origin
      xyz="0.00413596009601052 -0.0686389599620252 -0.249965785326798"
      rpy="0 0 0" />
    <parent
      link="l_leg_pitch" />
    <child
      link="l_knee" />
    <axis xyz="0 1 0" />
  </joint>
  <link name="l_foot_pitch">
    <inertial>
      <origin
        xyz="-2.2094915482114E-07 -0.0210002209491548 0.000142421968554962"
        rpy="0 0 0" />
      <mass
        value="0.00898868764931505" />
      <inertia
        ixx="8.64757693496474E-07"
        ixy="4.38814003822459E-16"
        ixz="3.49395618884054E-11"
        iyy="8.64757693496479E-07"
        iyz="-3.54041160032427E-11"
        izz="1.52124214524266E-06" />
    </inertial>
    <visual>
      <origin
        xyz="0 0 0"
        rpy="0 0 0" />
      <geometry>
        <mesh
          filename="../meshes/l_foot_pitch_simplify.STL" />
      </geometry>
      <material
        name="">
        <color
          rgba="0.807843137254902 0.843137254901961 0.905882352941176 1" />
      </material>
    </visual>
  </link>
  <joint name="l_foot_pitch"
    type="revolute"> <limit effort="1000.0" lower="-3.14" upper="3.14" velocity="0.5"/>
    <origin
      xyz="9.39839333040909E-05 0.0209999999999999 -0.346142421968556"
      rpy="0 0 0" />
    <parent
      link="l_knee" />
    <child
      link="l_foot_pitch" />
    <axis xyz="0 1 0" />
  </joint>
  <link name="l_foot_roll">
    <inertial>
      <origin
        xyz="-0.0432253086252035 -8.83109141272542E-06 -0.0231900309646781"
        rpy="0 0 0" />
      <mass
        value="0.48595336841054" />
      <inertia
        ixx="0.000157873471834251"
        ixy="1.96472635084532E-08"
        ixz="2.65605381022489E-06"
        iyy="0.000645275398662566"
        iyz="1.31456982241222E-08"
        izz="0.000765587215075718" />
    </inertial>
    <visual>
      <origin
        xyz="0 0 0"
        rpy="0 0 0" />
      <geometry>
        <mesh
          filename="../meshes/l_foot_roll_simplify.STL" />
      </geometry>
      <material
        name="">
        <color
          rgba="0.807843137254902 0.843137254901961 0.905882352941176 1" />
      </material>
    </visual>
  </link>
  <joint name="l_foot_roll"
    type="revolute"> <limit effort="1000.0" lower="-3.14" upper="3.14" velocity="0.5"/>
    <origin
      xyz="0.021 -0.021 0.000142421968555073"
      rpy="0 0 0" />
    <parent
      link="l_foot_pitch" />
    <child
      link="l_foot_roll" />
    <axis xyz="1 0 0" />
  </joint>
  <link name="r_leg_roll">
    <inertial>
      <origin
        xyz="0.0607646044341523 -0.000140365546816248 0.00228377101431822"
        rpy="0 0 0" />
      <mass
        value="0.11853067519234" />
      <inertia
        ixx="0.000100528224800769"
        ixy="8.59267223920867E-10"
        ixz="-5.7400764839374E-06"
        iyy="0.000266849167485496"
        iyz="1.09990636769441E-07"
        izz="0.000326431795353994" />
    </inertial>
    <visual>
      <origin
        xyz="0 0 0"
        rpy="0 0 0" />
      <geometry>
        <mesh
          filename="../meshes/r_leg_roll_simplify.STL" />
      </geometry>
      <material
        name="">
        <color
          rgba="0.807843137254902 0.843137254901961 0.905882352941176 1" />
      </material>
    </visual>
  </link>
  <joint name="r_leg_roll"
    type="revolute"> <limit effort="1000.0" lower="-3.14" upper="3.14" velocity="0.5"/>
    <origin
      xyz="-0.0756149468145449 -0.087 -0.0720754569616772"
      rpy="0 0 0" />
    <parent
      link="base_link" />
    <child
      link="r_leg_roll" />
    <axis xyz="1 0 0" />
  </joint>
  <link name="r_leg_yaw">
    <inertial>
      <origin
        xyz="0.000290901694932051 -0.0405086843275825 -0.100847259224443"
        rpy="0 0 0" />
      <mass
        value="0.204051628397563" />
      <inertia
        ixx="0.000304316594072443"
        ixy="-6.81313422907994E-07"
        ixz="5.14348465322562E-07"
        iyy="0.000364082222889467"
        iyz="-2.16425891305065E-06"
        izz="0.000267284560559922" />
    </inertial>
    <visual>
      <origin
        xyz="0 0 0"
        rpy="0 0 0" />
      <geometry>
        <mesh
          filename="../meshes/r_leg_yaw_simplify.STL" />
      </geometry>
      <material
        name="">
        <color
          rgba="0.862745098039216 0.933333333333333 0.929411764705882 1" />
      </material>
    </visual>
  </link>
  <joint name="r_leg_yaw"
    type="revolute"> <limit effort="1000.0" lower="-3.14" upper="3.14" velocity="0.5"/>
    <origin
      xyz="0.0735 0 0.0130000000000001"
      rpy="0 0 0" />
    <parent
      link="r_leg_roll" />
    <child
      link="r_leg_yaw" />
    <axis xyz="0 0 1" />
  </joint>
  <link name="r_leg_pitch">
    <inertial>
      <origin
        xyz="-0.00530844800069375 0.0879625104980525 -0.0562054035446188"
        rpy="0 0 0" />
      <mass
        value="0.448539615819603" />
      <inertia
        ixx="0.00148436919411102"
        ixy="2.29187023974564E-05"
        ixz="0.000131477003903541"
        iyy="0.00177802513573774"
        iyz="-7.48524907415416E-06"
        izz="0.000394727717573666" />
    </inertial>
    <visual>
      <origin
        xyz="0 0 0"
        rpy="0 0 0" />
      <geometry>
        <mesh
          filename="../meshes/r_leg_pitch_simplify.STL" />
      </geometry>
      <material
        name="">
        <color
          rgba="0.807843137254902 0.843137254901961 0.905882352941176 1" />
      </material>
    </visual>
  </link>
  <joint name="r_leg_pitch"
    type="revolute"> <limit effort="1000.0" lower="-3.14" upper="3.14" velocity="0.5"/>
    <origin
      xyz="0 -0.094 -0.13645"
      rpy="0 0 0" />
    <parent
      link="r_leg_yaw" />
    <child
      link="r_leg_pitch" />
    <axis xyz="0 1 0" />
  </joint>
  <link name="r_knee">
    <inertial>
      <origin
        xyz="0.000566315767979653 -0.000357175271787927 -0.138852368476045"
        rpy="0 0 0" />
      <mass
        value="0.345443991337626" />
      <inertia
        ixx="0.00281310613866549"
        ixy="1.11070732712115E-08"
        ixz="-2.80899108975025E-05"
        iyy="0.00291126127187274"
        iyz="2.42218525823218E-05"
        izz="0.000171958211692171" />
    </inertial>
    <visual>
      <origin
        xyz="0 0 0"
        rpy="0 0 0" />
      <geometry>
        <mesh
          filename="../meshes/r_knee_simplify.STL" />
      </geometry>
      <material
        name="">
        <color
          rgba="0.807843137254902 0.843137254901961 0.905882352941176 1" />
      </material>
    </visual>
  </link>
  <joint name="r_knee"
    type="revolute"> <limit effort="1000.0" lower="-3.14" upper="3.14" velocity="0.5"/>
    <origin
      xyz="0.00413596009601069 0.0685500000000013 -0.249965785326798"
      rpy="0 0 0" />
    <parent
      link="r_leg_pitch" />
    <child
      link="r_knee" />
    <axis xyz="0 1 0" />
  </joint>
  <link name="r_foot_pitch">
    <inertial>
      <origin
        xyz="-2.20949154776037E-07 0.0210002209491547 -1.11022302462516E-16"
        rpy="0 0 0" />
      <mass
        value="0.00898868764931501" />
      <inertia
        ixx="8.64757693496473E-07"
        ixy="-4.38813261088375E-16"
        ixz="-3.4939561888581E-11"
        iyy="8.64757693496477E-07"
        iyz="-3.44750077743079E-11"
        izz="1.52124214524266E-06" />
    </inertial>
    <visual>
      <origin
        xyz="0 0 0"
        rpy="0 0 0" />
      <geometry>
        <mesh
          filename="../meshes/r_foot_pitch_simplify.STL" />
      </geometry>
      <material
        name="">
        <color
          rgba="0.807843137254902 0.843137254901961 0.905882352941176 1" />
      </material>
    </visual>
  </link>
  <joint name="r_foot_pitch"
    type="revolute"> <limit effort="1000.0" lower="-3.14" upper="3.14" velocity="0.5"/>
    <origin
      xyz="0 -0.021 -0.346000000000001"
      rpy="0 0 0" />
    <parent
      link="r_knee" />
    <child
      link="r_foot_pitch" />
    <axis xyz="0 1 0" />
  </joint>
  <link name="r_foot_roll">
    <inertial>
      <origin
        xyz="-0.0480333310327909 6.50581714088661E-06 -0.0208399753329805"
        rpy="0 0 0" />
      <mass
        value="0.235882377040623" />
      <inertia
        ixx="7.44704948330087E-05"
        ixy="-1.32306351261624E-08"
        ixz="2.64137221389746E-06"
        iyy="0.000241939144027172"
        iyz="-4.67780047970378E-09"
        izz="0.000291936005980864" />
    </inertial>
    <visual>
      <origin
        xyz="0 0 0"
        rpy="0 0 0" />
      <geometry>
        <mesh
          filename="../meshes/r_foot_roll_simplify.STL" />
      </geometry>
      <material
        name="">
        <color
          rgba="0.807843137254902 0.843137254901961 0.905882352941176 1" />
      </material>
    </visual>
  </link>
  <joint name="r_foot_roll"
    type="revolute"> <limit effort="1000.0" lower="-3.14" upper="3.14" velocity="0.5"/>
    <origin
      xyz="0.021 0.0209999999999999 0"
      rpy="0 0 0" />
    <parent
      link="r_foot_pitch" />
    <child
      link="r_foot_roll" />
    <axis xyz="1 0 0" />
  </joint>
  <link name="real_camera_link">
    <inertial>
      <origin
        xyz="-0.00921266315655753 -0.00134236481905095 -0.000223201290186881"
        rpy="0 0 0" />
      <mass
        value="0.0173287679990781" />
      <inertia
        ixx="1.14349973374258E-05"
        ixy="-1.05355726979727E-07"
        ixz="-1.05868132715497E-08"
        iyy="9.5531115778752E-07"
        iyz="-1.61190264385732E-08"
        izz="1.07055967101248E-05" />
    </inertial>
    <visual>
      <origin
        xyz="0 0 0"
        rpy="0 0 0" />
      <geometry>
        <mesh
          filename="../meshes/real_camera_link_simplify.STL" />
      </geometry>
      <material
        name="">
        <color
          rgba="0.8 0.2 0.2 1" />
      </material>
    </visual>
  </link>
  <joint name="camera_joint"
    type="fixed">
    <origin
      xyz="0.078507 0.0026635 0.47328"
      rpy="0 0.61087 0" />
    <parent
      link="base_link" />
    <child
      link="real_camera_link" />
    <axis xyz="0 0 0" />
  </joint>
</robot>
